Workbook

Sheet Overview
A1: Naavik Unified UX — Feature Roadmap
A2: Living document. One row per domain; click a sheet tab for the full feature list.
A4: Domain | B4: Features | C4: Built | D4: In Progress | E4: Planned | F4: P0/P1 | G4: Sheet
A5: Platform & Auth | B5: =COUNTA('Platform & Auth'!A5:A15) | C5: =COUNTIF('Platform & Auth'!D5:D15,"Built") | D5: =COUNTIF('Platform & Auth'!D5:D15,"In Progress") | E5: =COUNTIF('Platform & Auth'!D5:D15,"Planned") | F5: =COUNTIF('Platform & Auth'!E5:E15,"P0")+COUNTIF('Platform & Auth'!E5:E15,"P1") | G5: → Platform & Auth
A6: Chat & Intent | B6: =COUNTA('Chat & Intent'!A5:A19) | C6: =COUNTIF('Chat & Intent'!D5:D19,"Built") | D6: =COUNTIF('Chat & Intent'!D5:D19,"In Progress") | E6: =COUNTIF('Chat & Intent'!D5:D19,"Planned") | F6: =COUNTIF('Chat & Intent'!E5:E19,"P0")+COUNTIF('Chat & Intent'!E5:E19,"P1") | G6: → Chat & Intent
A7: Naavik Observe | B7: =COUNTA('Naavik Observe'!A5:A26) | C7: =COUNTIF('Naavik Observe'!D5:D26,"Built") | D7: =COUNTIF('Naavik Observe'!D5:D26,"In Progress") | E7: =COUNTIF('Naavik Observe'!D5:D26,"Planned") | F7: =COUNTIF('Naavik Observe'!E5:E26,"P0")+COUNTIF('Naavik Observe'!E5:E26,"P1") | G7: → Naavik Observe
A8: Naavik AppGen | B8: =COUNTA('Naavik AppGen'!A5:A22) | C8: =COUNTIF('Naavik AppGen'!D5:D22,"Built") | D8: =COUNTIF('Naavik AppGen'!D5:D22,"In Progress") | E8: =COUNTIF('Naavik AppGen'!D5:D22,"Planned") | F8: =COUNTIF('Naavik AppGen'!E5:E22,"P0")+COUNTIF('Naavik AppGen'!E5:E22,"P1") | G8: → Naavik AppGen
A9: Naavik Provision | B9: =COUNTA('Naavik Provision'!A5:A10) | C9: =COUNTIF('Naavik Provision'!D5:D10,"Built") | D9: =COUNTIF('Naavik Provision'!D5:D10,"In Progress") | E9: =COUNTIF('Naavik Provision'!D5:D10,"Planned") | F9: =COUNTIF('Naavik Provision'!E5:E10,"P0")+COUNTIF('Naavik Provision'!E5:E10,"P1") | G9: → Naavik Provision
A10: Control Agent | B10: =COUNTA('Control Agent'!A5:A12) | C10: =COUNTIF('Control Agent'!D5:D12,"Built") | D10: =COUNTIF('Control Agent'!D5:D12,"In Progress") | E10: =COUNTIF('Control Agent'!D5:D12,"Planned") | F10: =COUNTIF('Control Agent'!E5:E12,"P0")+COUNTIF('Control Agent'!E5:E12,"P1") | G10: → Control Agent
A11: Knowledge Library | B11: =COUNTA('Knowledge Library'!A5:A11) | C11: =COUNTIF('Knowledge Library'!D5:D11,"Built") | D11: =COUNTIF('Knowledge Library'!D5:D11,"In Progress") | E11: =COUNTIF('Knowledge Library'!D5:D11,"Planned") | F11: =COUNTIF('Knowledge Library'!E5:E11,"P0")+COUNTIF('Knowledge Library'!E5:E11,"P1") | G11: → Knowledge Library
A12: Generative UI | B12: =COUNTA('Generative UI'!A5:A26) | C12: =COUNTIF('Generative UI'!D5:D26,"Built") | D12: =COUNTIF('Generative UI'!D5:D26,"In Progress") | E12: =COUNTIF('Generative UI'!D5:D26,"Planned") | F12: =COUNTIF('Generative UI'!E5:E26,"P0")+COUNTIF('Generative UI'!E5:E26,"P1") | G12: → Generative UI
A13: Data Layer | B13: =COUNTA('Data Layer'!A5:A22) | C13: =COUNTIF('Data Layer'!D5:D22,"Built") | D13: =COUNTIF('Data Layer'!D5:D22,"In Progress") | E13: =COUNTIF('Data Layer'!D5:D22,"Planned") | F13: =COUNTIF('Data Layer'!E5:E22,"P0")+COUNTIF('Data Layer'!E5:E22,"P1") | G13: → Data Layer
A14: Settings | B14: =COUNTA('Settings'!A5:A11) | C14: =COUNTIF('Settings'!D5:D11,"Built") | D14: =COUNTIF('Settings'!D5:D11,"In Progress") | E14: =COUNTIF('Settings'!D5:D11,"Planned") | F14: =COUNTIF('Settings'!E5:E11,"P0")+COUNTIF('Settings'!E5:E11,"P1") | G14: → Settings
A15: Demo Mode | B15: =COUNTA('Demo Mode'!A5:A9) | C15: =COUNTIF('Demo Mode'!D5:D9,"Built") | D15: =COUNTIF('Demo Mode'!D5:D9,"In Progress") | E15: =COUNTIF('Demo Mode'!D5:D9,"Planned") | F15: =COUNTIF('Demo Mode'!E5:E9,"P0")+COUNTIF('Demo Mode'!E5:E9,"P1") | G15: → Demo Mode
A16: TOTAL | B16: =SUM(B5:B15) | C16: =SUM(C5:C15) | D16: =SUM(D5:D15) | E16: =SUM(E5:E15) | F16: =SUM(F5:F15)
A19: Legend
A20: Status colors
A21: Built
A22: In Progress
A23: Planned
A24: Backlog
A25: Deferred
A27: Priority colors
A28: P0
A29: P1
A30: P2
A31: P3

Sheet Platform & Auth
A1: Platform & Auth
A2: 11 features
A4: ID | B4: Feature | C4: Description | D4: Status | E4: Priority | F4: Approval | G4: Owner | H4: Effort | I4: Target Version | J4: Target Quarter | K4: Dependencies | L4: Notes
A5: PF-001 | B5: JWT Login + 4-hour Persistent Session | C5: Username/password login with bcrypt + JWT. Token stored in localStorage. Frontend re-verifies on reload. | D5: Built | E5: P0 | F5: Approved | G5: Auth Team | H5: S | I5: v1.0 | J5: Q1 2026 | K5: — | L5: Live in prod
A6: PF-002 | B6: Env-Driven Admin Credentials | C6: Admin user/password/JWT secret read from .env. Lazy init handles ESM hoisting timing. Fails fast on missing config. | D6: Built | E6: P0 | F6: Approved | G6: Auth Team | H6: S | I6: v1.0 | J6: Q1 2026 | K6: PF-001 | L6: Hardened recently
A7: PF-003 | B7: Auth Context + Permission Gating | C7: AuthContext exposes user + per-app permissions. Components gate features via useAuth(). Permissions auto-refresh on user change. | D7: Built | E7: P0 | F7: Approved | G7: Frontend Platform | H7: M | I7: v1.0 | J7: Q1 2026 | K7: PF-001
A8: PF-004 | B8: First-Time Market Selector Modal | C8: Non-dismissable modal blocks app on first login until market is picked. Subsequent logins skip it. Persisted to localStorage. | D8: Built | E8: P1 | F8: Approved | G8: Frontend Platform | H8: S | I8: v1.1 | J8: Q2 2026 | K8: PF-005
A9: PF-005 | B9: Multi-Market Configuration | C9: Markets config in frontend/src/config/markets.ts. NorCal live; SoCal/PNW/TX/NE shown as 'Coming soon'. Maps labels to remote MARKET values. | D9: Built | E9: P1 | F9: Approved | G9: Frontend Platform | H9: S | I9: v1.1 | J9: Q2 2026 | K9: — | L9: More markets pending data
A10: PF-006 | B10: Theme Provider (Light/Dark) | C10: ThemeProvider exposes theme + setTheme. All bespoke components consume it. Defaults to dark; html.dark forced on bootstrap. | D10: Built | E10: P2 | F10: Approved | G10: Frontend Platform | H10: S | I10: v1.0 | J10: Q1 2026 | K10: —
A11: PF-007 | B11: User Profile Dropdown | C11: Sidebar avatar opens consolidated menu — Market / Settings / Feedback / Logout. Inline when expanded; portal popover when collapsed. | D11: Built | E11: P1 | F11: Approved | G11: Frontend Platform | H11: S | I11: v1.1 | J11: Q2 2026 | K11: PF-005, ST-001
A12: PF-008 | B12: Collapsible Left Sidebar | C12: Claude-style sidebar with collapse/expand, navigation rail, per-stream session history, profile menu at bottom. | D12: Built | E12: P1 | F12: Approved | G12: Frontend Platform | H12: M | I12: v1.1 | J12: Q2 2026 | K12: —
A13: PF-009 | B13: Platform Bus (Inter-App Navigation) | C13: Pub/sub bus for navigation intents (NAVIGATE_TO_APP). Shell subscribes and routes. Used by chat to deep-link into apps. | D13: Built | E13: P1 | F13: Approved | G13: Frontend Platform | H13: M | I13: v1.0 | J13: Q1 2026 | K13: —
A14: PF-010 | B14: App Registry | C14: Dynamic registry of mountable apps with display name, icon, route, default chat stream, permission key. Drives sidebar nav and AppSlot. | D14: Built | E14: P1 | F14: Approved | G14: Frontend Platform | H14: M | I14: v1.0 | J14: Q1 2026 | K14: PF-009
A15: PF-011 | B15: Login UI with Fluid Background | C15: Split-pane layout, animated fluid gradient background, theme-aware Naavik branding. Username + password + show/hide toggle. | D15: Built | E15: P2 | F15: Approved | G15: Design | H15: S | I15: v1.0 | J15: Q1 2026 | K15: PF-001

Sheet Chat & Intent
A1: Chat & Intent
A2: 15 features
A4: ID | B4: Feature | C4: Description | D4: Status | E4: Priority | F4: Approval | G4: Owner | H4: Effort | I4: Target Version | J4: Target Quarter | K4: Dependencies | L4: Notes
A5: CI-001 | B5: Multi-Stream Chat Orchestrator | C5: Five chat streams (universal, observability, appgen, provision, knowledge) with stream-specific prompts and starter suggestions. | D5: Built | E5: P0 | F5: Approved | G5: Agent Team | H5: M | I5: v1.0 | J5: Q1 2026 | K5: —
A6: CI-002 | B6: Agent V3 Orchestrator | C6: True OpenAI function-calling loop. Tools execute in parallel via Promise.allSettled. MAX_ITERATIONS=8, model gpt-4o-mini. | D6: Built | E6: P0 | F6: Approved | G6: Agent Team | H6: L | I6: v1.1 | J6: Q2 2026 | K6: —
A7: CI-003 | B7: 21-Tool Agent Registry | C7: Tools include find_site, get_worst_offenders, RCA, KPI dashboard, query_data, generate_report, knowledge, navigation. | D7: Built | E7: P0 | F7: Approved | G7: Agent Team | H7: L | I7: v1.0 | J7: Q1 2026 | K7: CI-002
A8: CI-004 | B8: Site-Analysis Tool Suite (10 tools) | C8: topology, config_changes, neighbor_relations, ret_changes, site_outages, neighbor_outages, hourly_trends, kpi_impact_breakdown, ticket_history, compare_with_cluster. | D8: Built | E8: P0 | F8: Approved | G8: Agent Team | H8: XL | I8: v1.1 | J8: Q2 2026 | K8: DL-002
A9: CI-005 | B9: Intent Classifier | C9: Semantic + explicit + context-aware classifier. Routes 'show map', 'explain RCA', 'build app' to the right stream and tool path. | D9: Built | E9: P1 | F9: Approved | G9: Agent Team | H9: M | I9: v1.0 | J9: Q1 2026 | K9: —
A10: CI-006 | B10: Navigation Orchestrator | C10: Three-layer intent detection turning chat into platform-bus events. 'Open observe' navigates; 'sites with alarms' also sets map layer. | D10: Built | E10: P1 | F10: Approved | G10: Agent Team | H10: M | I10: v1.0 | J10: Q1 2026 | K10: PF-009, CI-005
A11: CI-007 | B11: Conversation Context Service | C11: Persists thread state, history, metadata in PostgreSQL. Multi-turn conversations work across reloads. | D11: Built | E11: P1 | F11: Approved | G11: Backend Platform | H11: M | I11: v1.0 | J11: Q1 2026 | K11: —
A12: CI-008 | B12: Stop Button (Abort Controller) | C12: Send button morphs into Stop with spinning ring. Click aborts in-flight agentV3Chat via AbortController. Posts silent 'Request stopped' note. | D12: Built | E12: P1 | F12: Approved | G12: Frontend Platform | H12: S | I12: v1.2 | J12: Q2 2026 | K12: CI-002
A13: CI-009 | B13: Structured Synthesis Format | C13: System prompt requires six-section markdown synthesis. Powers DiagnosisCard. Severity / Headline / What Changed / Degraded / Root Cause / Next Actions. | D13: Built | E13: P1 | F13: Approved | G13: Agent Team | H13: S | I13: v1.2 | J13: Q2 2026 | K13: CI-002
A14: CI-010 | B14: Auto-Emit Diagnosis Card | C14: Orchestrator detects structured synthesis, injects diagnosis_card UI block, replaces chat-bubble text with just the headline. | D14: Built | E14: P1 | F14: Approved | G14: Agent Team | H14: M | I14: v1.2 | J14: Q2 2026 | K14: CI-009, UI-018
A15: CI-011 | B15: KPI / Parameter Resolver | C15: resolve_kpi_param tool fuzzy-matches user phrases against the 16k DataDict catalog. Surfaces chip selector when ambiguous. | D15: Built | E15: P1 | F15: Approved | G15: Knowledge Team | H15: M | I15: v1.0 | J15: Q1 2026 | K15: KN-002
A16: CI-012 | B16: Suggestion Chips & Starter Prompts | C16: Each chat stream has curated suggestions. Empty state shows starter chips. Home rotates placeholders. | D16: Built | E16: P2 | F16: Approved | G16: Frontend Platform | H16: S | I16: v1.0 | J16: Q1 2026 | K16: —
A17: CI-013 | B17: Multi-Attachment Support | C17: Up to 3 attachments per message — CSVs ≤750KB, images ≤900KB, text ≤120KB. Sent inline with chat payload. | D17: Built | E17: P2 | F17: Approved | G17: Frontend Platform | H17: M | I17: v1.0 | J17: Q1 2026 | K17: —
A18: CI-014 | B18: Per-Stream Session History | C18: Sidebar shows recent prompts grouped by stream. Click to re-send. History local to React state (not yet persisted). | D18: Built | E18: P2 | F18: Approved | G18: Frontend Platform | H18: S | I18: v1.0 | J18: Q1 2026 | K18: — | L18: Persistence planned for v1.3
A19: CI-015 | B19: V2 Chat Fallback | C19: Legacy V2 orchestrator (no tool calling) as fallback. Toggle via localStorage or Settings. | D19: Built | E19: P3 | F19: Approved | G19: Agent Team | H19: S | I19: v0.9 | J19: Q4 2025 | K19: — | L19: Will be deprecated in v2.0

Sheet Naavik Observe
A1: Naavik Observe
A2: 22 features
A4: ID | B4: Feature | C4: Description | D4: Status | E4: Priority | F4: Approval | G4: Owner | H4: Effort | I4: Target Version | J4: Target Quarter | K4: Dependencies | L4: Notes
A5: OB-001 | B5: Mapbox Site Map | C5: Interactive Mapbox-GL map showing 6,800+ sites for selected market. Zoom/pan/click. Color-coded by severity. | D5: Built | E5: P0 | F5: Approved | G5: Observe Team | H5: L | I5: v1.0 | J5: Q1 2026 | K5: DL-014
A6: OB-002 | B6: Site Layer Toggles | C6: Three layers — degraded, outage, overutilized. Driven by set_map_layer from chat or direct UI clicks. | D6: Built | E6: P0 | F6: Approved | G6: Observe Team | H6: M | I6: v1.0 | J6: Q1 2026 | K6: OB-001
A7: OB-003 | B7: Site Detail Panel — 5 Tabs | C7: Click site → tabbed panel. Site KPI, RCA, Operational, Topology, AI Analyzer. Summary vs Diagnostic mode toggle. | D7: Built | E7: P0 | F7: Approved | G7: Observe Team | H7: L | I7: v1.1 | J7: Q2 2026 | K7: OB-001
A8: OB-004 | B8: Summary Mode (Animated RCA) | C8: RCA-focused summary with step-by-step strongest-factors animation, mini-map for related neighbors. | D8: Built | E8: P1 | F8: Approved | G8: Observe Team | H8: M | I8: v1.0 | J8: Q1 2026 | K8: OB-003
A9: OB-005 | B9: Diagnostic Mode | C9: Full telemetry — KPI charts, hourly insights, anomaly callouts. Sub-second loads via local mirror. | D9: Built | E9: P0 | F9: Approved | G9: Observe Team | H9: L | I9: v1.2 | J9: Q2 2026 | K9: DL-002, DL-012
A10: OB-006 | B10: Cell Topology View | C10: Cells listed with band, technology, azimuth, height, anomaly. Replaced by TopologyGrid (band tiles). | D10: Built | E10: P1 | F10: Approved | G10: Observe Team | H10: M | I10: v1.2 | J10: Q2 2026 | K10: UI-020
A11: OB-007 | B11: KPI Dashboard (Daily/Hourly) | C11: Multi-KPI line-chart with daily 7-90d / hourly 24-72h. KPI selector with 16 grouped standard KPIs + custom search. | D11: Built | E11: P0 | F11: Approved | G11: Observe Team | H11: L | I11: v1.0 | J11: Q1 2026 | K11: DL-015
A12: OB-008 | B12: Multi-KPI Comparison | C12: Up to 8 KPIs simultaneously, unit-aware Y-axis, anomaly markers, shared 20-color palette. | D12: Built | E12: P1 | F12: Approved | G12: Observe Team | H12: M | I12: v1.0 | J12: Q1 2026 | K12: OB-007
A13: OB-009 | B13: Hourly Insights Panel | C13: Time-of-day pattern analysis — peak hours, busy-hour deviation, anomaly hours, weekly comparison. | D13: Built | E13: P1 | F13: Approved | G13: Observe Team | H13: M | I13: v1.1 | J13: Q2 2026 | K13: OB-007
A14: OB-010 | B14: Mobility Trends | C14: HOSR, inter/intra-frequency HO, throughput-per-handover. Used by analyzer for coverage detection. | D14: Built | E14: P2 | F14: Approved | G14: Observe Team | H14: M | I14: v1.1 | J14: Q2 2026 | K14: —
A15: OB-011 | B15: Outage Timeline | C15: Per-cell outage events on 24h or 7d strip. Shows metric type and snapshot hour. | D15: Built | E15: P2 | F15: Approved | G15: Observe Team | H15: M | I15: v1.1 | J15: Q2 2026 | K15: —
A16: OB-012 | B16: Traffic Profile Dashboard | C16: DL/UL volume + PRB-utilisation profile. Distinguishes capacity from coverage issues. | D16: Built | E16: P2 | F16: Approved | G16: Observe Team | H16: M | I16: v1.1 | J16: Q2 2026 | K16: —
A17: OB-013 | B17: Cross-Correlator (KPI Relationships) | C17: Pairwise correlation between KPIs. Surfaces which pairs move together or diverge. | D17: Planned | E17: P2 | F17: Pending | G17: Observe Team | H17: L | I17: v1.4 | J17: Q3 2026 | K17: OB-007 | L17: Removed for redesign
A18: OB-014 | B18: AI Analyzer Tab | C18: Dedicated tab in site detail. Runs deep investigation (8-10 tools parallel). Hero severity card + 4 verdict sections + trail + evidence. | D18: Built | E18: P0 | F18: Approved | G18: Agent Team | H18: L | I18: v1.2 | J18: Q2 2026 | K18: CI-002, CI-004
A19: OB-015 | B19: Worst Offenders Ranking | C19: Daily ranked list by total CQX impact. Each row links to site detail. Inline 'Explain RCA' button. | D19: Built | E19: P0 | F19: Approved | G19: Observe Team | H19: M | I19: v1.0 | J19: Q1 2026 | K19: DL-002
A20: OB-016 | B20: Cluster Comparison | C20: Site KPI vs cluster peers. Returns rank, percentile, outlier flag (>2σ). Bar chart with source highlighted. | D20: Built | E20: P1 | F20: Approved | G20: Agent Team | H20: M | I20: v1.2 | J20: Q2 2026 | K20: CI-004
A21: OB-017 | B21: Neighbor Map Overlay | C21: Top neighbors as dashed lines on map with HO-share labels. Click pivots panel to that site. | D21: Built | E21: P1 | F21: Approved | G21: Observe Team | H21: M | I21: v1.1 | J21: Q2 2026 | K21: OB-001, OB-003
A22: OB-018 | B22: Operational Info Workbench | C22: Aggregates alarms, tickets, config, outages, EIM for site + neighbors over 7d. Sub-tabs per type. | D22: Built | E22: P1 | F22: Approved | G22: Observe Team | H22: L | I22: v1.1 | J22: Q2 2026 | K22: DL-002
A23: OB-019 | B23: Compass Dashboard (KPI Tiles) | C23: Market-level dashboard tile grid showing aggregated KPIs across selected sites. At-a-glance Network Management home. | D23: Built | E23: P1 | F23: Approved | G23: Observe Team | H23: M | I23: v1.0 | J23: Q1 2026 | K23: DL-015
A24: OB-020 | B24: Telemetry Dashboard with Gauges + Heatmaps | C24: Professional 5-tab telemetry — semicircular gauge charts, hourly heatmaps, KPI trend mini-charts. | D24: Built | E24: P1 | F24: Approved | G24: Observe Team | H24: L | I24: v1.1 | J24: Q2 2026 | K24: OB-007
A25: OB-021 | B25: Map Chat Bar | C25: Persistent chat input docked to map view. Pre-fills with selected site's USID for quick 'what's wrong here?' queries. | D25: Built | E25: P1 | F25: Approved | G25: Observe Team | H25: M | I25: v1.0 | J25: Q1 2026 | K25: CI-001
A26: OB-022 | B26: Site Status Pills | C26: TOP DEGRADED / OUTAGE pulse pills in panel header for offender sites. Pulled from cqx_offenders + site.outage. | D26: Built | E26: P2 | F26: Approved | G26: Observe Team | H26: S | I26: v1.0 | J26: Q1 2026 | K26: —

Sheet Naavik AppGen
A1: Naavik AppGen
A2: 18 features
A4: ID | B4: Feature | C4: Description | D4: Status | E4: Priority | F4: Approval | G4: Owner | H4: Effort | I4: Target Version | J4: Target Quarter | K4: Dependencies | L4: Notes
A5: AG-001 | B5: 6-Stage AI App Pipeline | C5: Planning → Code Gen → Audit → Unit Test → Integration → Assembly. State machine with backward navigation. | D5: Built | E5: P0 | F5: Approved | G5: AppGen Team | H5: XL | I5: v1.0 | J5: Q1 2026 | K5: —
A6: AG-002 | B6: Planning Agent | C6: Takes NL requirement, produces structured plan: target KPI, trigger, action, scope, failure modes. User approves before code gen. | D6: Built | E6: P0 | F6: Approved | G6: AppGen Team | H6: L | I6: v1.0 | J6: Q1 2026 | K6: AG-001
A7: AG-003 | B7: Code Generation Agent | C7: Generates rApp code, config YAML, K8s manifests, tests. Live file panel updates. Monaco editor for inline edit. | D7: Built | E7: P0 | F7: Approved | G7: AppGen Team | H7: XL | I7: v1.0 | J7: Q1 2026 | K7: AG-002
A8: AG-004 | B8: Code Audit Agent | C8: Static analysis — security (no embedded secrets, safe SQL), correctness (parameter ranges, KPI validity), style. | D8: Built | E8: P1 | F8: Approved | G8: AppGen Team | H8: L | I8: v1.0 | J8: Q1 2026 | K8: AG-003
A9: AG-005 | B9: Unit Test Agent | C9: Generates and runs unit tests in sandboxed runner. Failures surface inline with assertion details. | D9: Built | E9: P1 | F9: Approved | G9: AppGen Team | H9: L | I9: v1.0 | J9: Q1 2026 | K9: AG-003
A10: AG-006 | B10: Integration Validation Agent | C10: End-to-end smoke test against simulated network. Feeds rApp synthetic KPI streams, validates control actions. | D10: Built | E10: P1 | F10: Approved | G10: AppGen Team | H10: L | I10: v1.1 | J10: Q2 2026 | K10: PV-002
A11: AG-007 | B11: App Assembly Agent | C11: Packages code + tests + manifests + metadata into deployable bundle. Produces zip and 'publish to catalog' action. | D11: Built | E11: P1 | F11: Approved | G11: AppGen Team | H11: M | I11: v1.1 | J11: Q2 2026 | K11: AG-013
A12: AG-008 | B12: Conversational App Builder | C12: Free-form chat for app creation. Asks clarifying questions when requirement is ambiguous. | D12: Built | E12: P0 | F12: Approved | G12: AppGen Team | H12: L | I12: v1.0 | J12: Q1 2026 | K12: CI-001
A13: AG-009 | B13: Scaffold Confirmation | C13: Before code gen, agent shows file scaffold (which files, what they contain). User approves or rejects. | D13: Built | E13: P1 | F13: Approved | G13: AppGen Team | H13: M | I13: v1.0 | J13: Q1 2026 | K13: AG-002
A14: AG-010 | B14: Real-Time File Generation Panel | C14: Streamed file writes appear live. Each file shows progress + syntax-highlighted preview when done. | D14: Built | E14: P1 | F14: Approved | G14: AppGen Team | H14: M | I14: v1.0 | J14: Q1 2026 | K14: AG-003
A15: AG-011 | B15: Workflow State Machine + Backward Nav | C15: 6-stage pipeline persists per project. Rewind to any stage, edit, re-run forward. | D15: Built | E15: P1 | F15: Approved | G15: AppGen Team | H15: L | I15: v1.0 | J15: Q1 2026 | K15: AG-001
A16: AG-012 | B16: Multi-Project Workspace | C16: Side-by-side project switcher. Each project keeps own files, conversation, pipeline state. | D16: Built | E16: P2 | F16: Approved | G16: AppGen Team | H16: M | I16: v1.1 | J16: Q2 2026 | K16: AG-001
... A22: AG-018 | B22: Agent Activity Rail | C22: Live progress rail — current agent, tool called, time remaining. Useful for monitoring long pipelines. | D22: Built | E22: P2 | F22: Approved | G22: Frontend Platform | H22: M | I22: v1.1 | J22: Q2 2026 | K22: AG-001

Sheet Naavik Provision
A1: Naavik Provision
A2: 6 features
A4: ID | B4: Feature | C4: Description | D4: Status | E4: Priority | F4: Approval | G4: Owner | H4: Effort | I4: Target Version | J4: Target Quarter | K4: Dependencies | L4: Notes
A5: PV-001 | B5: Provisioning Workflow Simulator | C5: Simulates change-management — request, approval, OSS push, validation. No real network impact. | D5: Built | E5: P0 | F5: Approved | G5: Provision Team | H5: L | I5: v1.1 | J5: Q2 2026 | K5: —
A6: PV-002 | B6: OSS Adapter Framework | C6: Pluggable connector interface for ENM, MOSES, etc. Simulator implements the same interface. | D6: Built | E6: P0 | F6: Approved | G6: Provision Team | H6: L | I6: v1.1 | J6: Q2 2026 | K6: —
A7: PV-003 | B7: ENM Connector | C7: Direct integration with Ericsson Network Manager for parameter changes. Feature-flagged per market. | D7: In Progress | E7: P1 | F7: Pending | G7: Provision Team | H7: L | I7: v1.3 | J7: Q3 2026 | K7: PV-002 | L7: Awaiting cred provisioning
A8: PV-004 | B8: Provisioning Candidate Site UI | C8: Sites flagged for parameter changes with current vs proposed values, expected KPI delta, one-click submit. | D8: Built | E8: P1 | F8: Approved | G8: Provision Team | H8: M | I8: v1.1 | J8: Q2 2026 | K8: PV-001
A9: PV-005 | B9: Change Request Flow | C9: Multi-step form: target sites, parameter, old/new values, justification, target window. Integrates rApp builder. | D9: Built | E9: P1 | F9: Approved | G9: Provision Team | H9: L | I9: v1.1 | J9: Q2 2026 | K9: PV-001, AG-001
A10: PV-006 | B10: Provisioning Status Tracking | C10: Status board for in-flight, completed, failed changes. Each row exposes OSS audit log + rollback option. | D10: Built | E10: P1 | F10: Approved | G10: Provision Team | H10: M | I10: v1.1 | J10: Q2 2026 | K10: PV-001

Sheet Control Agent
A1: Control Agent
A2: 8 features
A4: ID | B4: Feature | C4: Description | D4: Status | E4: Priority | F4: Approval | G4: Owner | H4: Effort | I4: Target Version | J4: Target Quarter | K4: Dependencies | L4: Notes
A5: CA-001 | B5: Automation Pipeline Service | C5: Backend orchestrator — chat-triggered intent → rApp build → OSS push → KPI validation. PG-persisted state. | D5: Built | E5: P0 | F5: Approved | G5: Agent Team | H5: XL | I5: v1.1 | J5: Q2 2026 | K5: CI-002, AG-001, PV-002
A6: CA-002 | B6: Workflow Generator | C6: High-level goal → executable workflow JSON with steps, triggers, rollback logic. | D6: Built | E6: P1 | F6: Approved | G6: Agent Team | H6: L | I6: v1.1 | J6: Q2 2026 | K6: CA-001
A7: CA-003 | B7: OSS Adapter Simulator | C7: In-process simulator mimicking OSS responses (success/failure, latency, parameter validation). Dev/demo safe. | D7: Built | E7: P1 | F7: Approved | G7: Provision Team | H7: M | I7: v1.1 | J7: Q2 2026 | K7: PV-002
A8: CA-004 | B8: Execution Status Polling | C8: Polls automation status from backend at 2s intervals. Renders in WorkflowExecutionStatus UI block. | D8: Built | E8: P1 | F8: Approved | G8: Frontend Platform | H8: S | I8: v1.1 | J8: Q2 2026 | K8: CA-001, UI-013
A9: CA-005 | B9: Agent Automation Report | C9: Final report after workflow — steps executed, OSS responses, KPI deltas measured, success/failure verdict. | D9: Built | E9: P1 | F9: Approved | G9: Agent Team | H9: M | I9: v1.1 | J9: Q2 2026 | K9: CA-001
A10: CA-006 | B10: Multi-Step Workflow Display | C10: Stage-by-stage UI — each automation step with status (pending/running/done/failed) and per-step duration. | D10: Built | E10: P1 | F10: Approved | G10: Frontend Platform | H10: M | I10: v1.1 | J10: Q2 2026 | K10: UI-013
A11: CA-007 | B11: Change-Parameter Intent Execution | C11: Chat intent like 'increase qRxLevMin by 2dB on USID 9787' triggers full pipeline — validate, draft, queue, push, monitor. | D11: Built | E11: P1 | F11: Approved | G11: Agent Team | H11: L | I11: v1.1 | J11: Q2 2026 | K11: CA-001, KN-002
A12: CA-008 | B12: Traffic Balancing Automation | C12: Pre-built template for HOSR-driven balancing — picks neighbor relations, computes offsets, pushes through OSS. | D12: Built | E12: P1 | F12: Approved | G12: Agent Team | H12: L | I12: v1.1 | J12: Q2 2026 | K12: CA-001

Sheet Knowledge Library
A1: Knowledge Library
A2: 7 features
A4: ID | B4: Feature | C4: Description | D4: Status | E4: Priority | F4: Approval | G4: Owner | H4: Effort | I4: Target Version | J4: Target Quarter | K4: Dependencies | L4: Notes
A5: KN-001 | B5: Telecom Knowledge Service | C5: Q&A engine grounded in DataDict. Answers 'what is qRxLevMin?' with description, range, default, usage notes. | D5: Built | E5: P0 | F5: Approved | G5: Knowledge Team | H5: L | I5: v1.0 | J5: Q1 2026 | K5: KN-002
A6: KN-002 | B6: DataDict Resolver (16k Parameters) | C6: In-memory index of 16,038 Ericsson EIAP telco_RAN parameters. Exact, prefix, fuzzy match. Disk-warmed on boot. | D6: Built | E6: P0 | F6: Approved | G6: Knowledge Team | H6: L | I6: v1.0 | J6: Q1 2026 | K6: —
A7: KN-003 | B7: Fuzzy Match KPI / Parameter Lookup | C7: Trigram fuzzy match for misspelled/informal names. Returns ranked candidates with confidence. | D7: Built | E7: P0 | F7: Approved | G7: Knowledge Team | H7: M | I7: v1.0 | J7: Q1 2026 | K7: KN-002
A8: KN-004 | B8: Knowledge Stream Chat | C8: Dedicated chat stream routing all queries through knowledge tool. Answer cards with definition, range, related params. | D8: Built | E8: P1 | F8: Approved | G8: Knowledge Team | H8: M | I8: v1.0 | J8: Q1 2026 | K8: CI-001, KN-001
A9: KN-005 | B9: Parameter-to-KPI Mapper | C9: Reverse lookup — given a KPI, list parameters that influence it. 'Which parameters affect drop rate?' queries. | D9: Built | E9: P1 | F9: Approved | G9: Knowledge Team | H9: M | I9: v1.0 | J9: Q1 2026 | K9: KN-002
A10: KN-006 | B10: Schema Registry | C10: Backend cache of remote DB column types + KPI catalog. Refreshes hourly. Used by SQL generator. | D10: Built | E10: P1 | F10: Approved | G10: Backend Platform | H10: M | I10: v1.0 | J10: Q1 2026 | K10: —
A11: KN-007 | B11: CSV RAG Resolver | C11: Retrieval-augmented resolver for CSV-uploaded scenario data. Answers about user's own data file. | D11: Built | E11: P2 | F11: Approved | G11: Knowledge Team | H11: M | I11: v1.0 | J11: Q1 2026 | K11: —

Sheet Generative UI
A1: Generative UI
A2: 22 features
A4: ID | B4: Feature | C4: Description | D4: Status | E4: Priority | F4: Approval | G4: Owner | H4: Effort | I4: Target Version | J4: Target Quarter | K4: Dependencies | L4: Notes
A5: UI-001 | B5: UiBlocksRenderer | C5: Central renderer mapping every uiBlock type to a React component. 18+ types. Auto-pairs adjacent compact tables. | D5: Built | E5: P0 | F5: Approved | G5: Frontend Platform | H5: L | I5: v1.0 | J5: Q1 2026 | K5: —
A6: UI-002 | B6: data_table (AG-Grid) | C6: Heavy interactive table with filter, sort, virtualization, Explain-RCA button. For multi-site lists. | D6: Built | E6: P0 | F6: Approved | G6: Frontend Platform | H6: M | I6: v1.0 | J6: Q1 2026 | K6: UI-001
A7: UI-003 | B7: compact_table | C7: Lightweight dense table — auto numeric/cell-name/anomaly detection, no Explain button. For single-USID context. | D7: Built | E7: P0 | F7: Approved | G7: Frontend Platform | H7: M | I7: v1.2 | J7: Q2 2026 | K7: UI-001
A8: UI-004 | B8: kpi_dashboard | C8: Interactive multi-KPI chart panel. Daily/hourly toggle, KPI selector, save-to-dashboard, collapse-after-N-groups. | D8: Built | E8: P0 | F8: Approved | G8: Frontend Platform | H8: L | I8: v1.0 | J8: Q1 2026 | K8: DL-015
A9: UI-005 | B9: insight_chart | C9: Single ECharts panel with title, subtitle, full ECharts option object. Most flexible chart type. | D9: Built | E9: P1 | F9: Approved | G9: Frontend Platform | H9: M | I9: v1.0 | J9: Q1 2026 | K9: UI-001
A10: UI-006 | B10: stat_row | C10: Horizontal row of label/value stat tiles. Compact way to surface a handful of metrics. | D10: Built | E10: P1 | F10: Approved | G10: Frontend Platform | H10: S | I10: v1.0 | J10: Q1 2026 | K10: UI-001
A11: UI-007 | B11: callout (toned info box) | C11: Tone-colored box — info, success, warning, error. Icon + text. | D11: Built | E11: P1 | F11: Approved | G11: Frontend Platform | H11: S | I11: v1.0 | J11: Q1 2026 | K11: UI-001
A12: UI-008 | B12: chips (interactive prompts) | C12: Row of clickable pill buttons. Each chip emits a chat prompt. Used for KPI disambiguation. | D12: Built | E12: P1 | F12: Approved | G12: Frontend Platform | H12: S | I12: v1.0 | J12: Q1 2026 | K12: UI-001
A13: UI-009 | B13: ranked_list | C13: Vertical ranked list — severity dot, value, trend sparkline. Compact offender lists. | D13: Built | E13: P1 | F13: Approved | G13: Frontend Platform | H13: M | I13: v1.0 | J13: Q1 2026 | K13: UI-001
A14: UI-010 | B14: rca_story | C14: Narrative-style RCA card — chain-of-thought steps, evidence, conclusion. For summary-mode RCA views. | D14: Built | E14: P1 | F14: Approved | G14: Frontend Platform | H14: L | I14: v1.0 | J14: Q1 2026 | K14: UI-001
A15: UI-011 | B15: rca_summary / rca_report | C15: Condensed RCA cards — bucket category, confidence score, short summary. First thing user sees on degraded site. | D15: Built | E15: P1 | F15: Approved | G15: Frontend Platform | H15: M | I15: v1.0 | J15: Q1 2026 | K15: UI-001
A16: UI-012 | B16: ticket_escalation | C16: Card prompting user to escalate finding to NOC. Pre-filled with site context. | D16: Built | E16: P2 | F16: Approved | G16: Frontend Platform | H16: M | I16: v1.0 | J16: Q1 2026 | K16: UI-001
... A26: UI-022 | B26: Saved Dashboards Manager | C26: Sidebar list of saved dashboards — one-click reload, rename, delete. | D26: Built | E26: P2 | F26: Approved | G26: Frontend Platform | H26: M | I26: v1.1 | J26: Q2 2026 | K26: UI-021

Sheet Data Layer
A1: Data Layer
A2: 18 features
A4: ID | B4: Feature | C4: Description | D4: Status | E4: Priority | F4: Approval | G4: Owner | H4: Effort | I4: Target Version | J4: Target Quarter | K4: Dependencies | L4: Notes
A5: DL-001 | B5: NaavikDBConnector | C5: TypeScript port of Python remote DB connector. POSTs SQL to remote query endpoint, returns parsed rows. | D5: Built | E5: P0 | F5: Approved | G5: Backend Platform | H5: M | I5: v1.0 | J5: Q1 2026 | K5: —
A6: DL-002 | B6: Local Postgres Mirror Schema | C6: Dedicated mirror.* schema in local PG holding faithful copies of 14 remote tables. Same names (lowercased). | D6: Built | E6: P0 | F6: Approved | G6: Backend Platform | H6: L | I6: v1.2 | J6: Q2 2026 | K6: —
A7: DL-003 | B7: Schema Discovery from MSSQL | C7: Auto-generates DDL by reading INFORMATION_SCHEMA.COLUMNS. Maps MSSQL types to PG. Re-runs on every boot. | D7: Built | E7: P0 | F7: Approved | G7: Backend Platform | H7: M | I7: v1.2 | J7: Q2 2026 | K7: DL-002
A8: DL-004 | B8: Offender-Only Mirror Strategy | C8: Mirror contains only rows for offender USIDs (chain_of_thought IS NOT NULL). ~50-100 USIDs/day × 30 days. | D8: Built | E8: P0 | F8: Approved | G8: Backend Platform | H8: M | I8: v1.2 | J8: Q2 2026 | K8: DL-002
A9: DL-005 | B9: 30-Day Backfill on First Boot | C9: Non-blocking 30-day backfill on first start. Days run sequentially; tables in parallel batches of 4. | D9: Built | E9: P0 | F9: Approved | G9: Backend Platform | H9: M | I9: v1.2 | J9: Q2 2026 | K9: DL-002, DL-003
A10: DL-006 | B10: Daily Incremental Sync (03:00 UTC) | C10: Cron-style scheduler runs runForDate(yesterday) daily. Configurable via MIRROR_DAILY_HOUR_UTC env. | D10: Built | E10: P0 | F10: Approved | G10: Backend Platform | H10: S | I10: v1.2 | J10: Q2 2026 | K10: DL-005
A11: DL-007 | B11: 30-Day Retention Sweep | C11: After every daily sync, prunes rows older than 30 days. Bounded storage + fast queries. | D11: Built | E11: P0 | F11: Approved | G11: Backend Platform | H11: S | I11: v1.2 | J11: Q2 2026 | K11: DL-006
A12: DL-008 | B12: USID Chunking for High-Cardinality Tables | C12: hourly_intermediate_kpis chunks offender USIDs (5/chunk, 3 concurrent). Avoids 10-min query timeouts. | D12: Built | E12: P0 | F12: Approved | G12: Backend Platform | H12: M | I12: v1.2 | J12: Q2 2026 | K12: DL-005
A13: DL-009 | B13: SARGable Date Predicates | C13: Mirror queries use date_id::date BETWEEN $1 AND $2 instead of CAST(DATE_ID AS DATE) =. Index-friendly. | D13: Built | E13: P0 | F13: Approved | G13: Backend Platform | H13: S | I13: v1.2 | J13: Q2 2026 | K13: DL-002
A14: DL-010 | B14: Mirror Run Log | C14: mirror.run_log records every (date, table) sync — row counts, durations, errors. Surfaced via /api/mirror/status. | D14: Built | E14: P1 | F14: Approved | G14: Backend Platform | H14: S | I14: v1.2 | J14: Q2 2026 | K14: DL-005
A15: DL-011 | B15: Mirror Admin Endpoints | C15: POST /api/mirror/backfill?days=30 and GET /api/mirror/status. JWT-protected. | D15: Built | E15: P1 | F15: Approved | G15: Backend Platform | H15: S | I15: v1.2 | J15: Q2 2026 | K15: DL-010
A16: DL-012 | B16: mirrorOrRemote Query Router | C16: Local-first generic helper. 0 rows or error → transparent remote fallback. Used by all site-analysis tools and KPI dashboard. | D16: Built | E16: P0 | F16: Approved | G16: Backend Platform | H16: M | I16: v1.2 | J16: Q2 2026 | K16: DL-002
... A22: DL-018 | B22: DB Schema Reference Cache | C22: Hourly-refreshed cache of distinct KPI names, subcomponent names, column lists. Used by SQL generator + resolver. | D22: Built | E22: P1 | F22: Approved | G22: Backend Platform | H22: M | I22: v1.0 | J22: Q1 2026 | K22: —

Sheet Settings
A1: Settings
A2: 7 features
A4: ID | B4: Feature | C4: Description | D4: Status | E4: Priority | F4: Approval | G4: Owner | H4: Effort | I4: Target Version | J4: Target Quarter | K4: Dependencies | L4: Notes
A5: ST-001 | B5: Settings Page (Tabbed) | C5: Dedicated /settings view with tabs — User Profile, AppGen Config, KPI Library, App Permissions, System Preferences. | D5: Built | E5: P1 | F5: Approved | G5: Frontend Platform | H5: M | I5: v1.0 | J5: Q1 2026 | K5: —
A6: ST-002 | B6: AppGen Settings | C6: Per-user defaults — preferred LLM model, K8s context, OSS adapter, default scaffold options. | D6: Built | E6: P1 | F6: Approved | G6: AppGen Team | H6: M | I6: v1.1 | J6: Q2 2026 | K6: ST-001
A7: ST-003 | B7: KPI Library | C7: Edit standard KPI groups + custom user-saved KPIs. Persisted in PG. | D7: Built | E7: P2 | F7: Approved | G7: Frontend Platform | H7: M | I7: v1.1 | J7: Q2 2026 | K7: ST-001
A8: ST-004 | B8: User-App Permission Matrix | C8: Admin-only UI for grant/revoke per-user app access. Backed by user_app_permissions table. | D8: Built | E8: P1 | F8: Approved | G8: Backend Platform | H8: L | I8: v1.1 | J8: Q2 2026 | K8: ST-001, PF-003
A9: ST-005 | B9: Theme Toggle | C9: Light / Dark / Auto switch. Auto follows OS preference. | D9: Built | E9: P2 | F9: Approved | G9: Frontend Platform | H9: S | I9: v1.0 | J9: Q1 2026 | K9: PF-006
A10: ST-006 | B10: Demo Mode Toggle | C10: Master switch enabling dummifier across the app. localStorage-persisted. | D10: Built | E10: P1 | F10: Approved | G10: Frontend Platform | H10: S | I10: v1.0 | J10: Q1 2026 | K10: DM-001
A11: ST-007 | B11: Profile Management | C11: User can update display name, email, notification preferences. | D11: Planned | E11: P3 | F11: Pending | G11: Frontend Platform | H11: S | I11: v1.4 | J11: Q3 2026 | K11: ST-001

Sheet Demo Mode
A1: Demo Mode
A2: 5 features
A4: ID | B4: Feature | C4: Description | D4: Status | E4: Priority | F4: Approval | G4: Owner | H4: Effort | I4: Target Version | J4: Target Quarter | K4: Dependencies | L4: Notes
A5: DM-001 | B5: Dummifier Provider | C5: React context exposing dId(usid) to mask real USIDs as UST######. Wraps every visible USID in the app. | D5: Built | E5: P1 | F5: Approved | G5: Frontend Platform | H5: M | I5: v1.0 | J5: Q1 2026 | K5: —
A6: DM-002 | B6: Reverse Mapping for Chat | C6: When user types UST###### in chat, unmapText() translates back to real USID before sending to backend. | D6: Built | E6: P1 | F6: Approved | G6: Frontend Platform | H6: S | I6: v1.0 | J6: Q1 2026 | K6: DM-001
A7: DM-003 | B7: Persistent Demo Toggle | C7: Demo mode survives reloads via localStorage('naavik_dummifier_enabled'). Controlled from Settings. | D7: Built | E7: P1 | F7: Approved | G7: Frontend Platform | H7: S | I7: v1.0 | J7: Q1 2026 | K7: DM-001, ST-006
A8: DM-004 | B8: Auto-Register Real IDs | C8: Whenever live sites list updates, MapDataContext registers all real USIDs with dummifier so reverse-lookup stays warm. | D8: Built | E8: P2 | F8: Approved | G8: Frontend Platform | H8: S | I8: v1.0 | J8: Q1 2026 | K8: DM-001
A9: DM-005 | B9: Settings Page Integration | C9: Toggle surfaced as single switch in Settings → System Preferences with explanatory hint. | D9: Built | E9: P2 | F9: Approved | G9: Frontend Platform | H9: S | I9: v1.0 | J9: Q1 2026 | K9: ST-006

Sheet All Features
A1: Master Feature List (flat — sort and filter across all domains)
A3: Domain | B3: ID | C3: Feature | D3: Description | E3: Status | F3: Priority | G3: Approval | H3: Owner | I3: Effort | J3: Target Version | K3: Target Quarter | L3: Dependencies | M3: Notes
A4: Platform & Auth | B4: PF-001 | C4: JWT Login + 4-hour Persistent Session | D4: Username/password login with bcrypt + JWT. Token stored in localStorage. Frontend re-verifies on reload. | E4: Built | F4: P0 | G4: Approved | H4: Auth Team | I4: S | J4: v1.0 | K4: Q1 2026 | L4: — | M4: Live in prod
A5: Platform & Auth | B5: PF-002 | C5: Env-Driven Admin Credentials | D5: Admin user/password/JWT secret read from .env. Lazy init handles ESM hoisting timing. Fails fast on missing config. | E5: Built | F5: P0 | G5: Approved | H5: Auth Team | I5: S | J5: v1.0 | K5: Q1 2026 | L5: PF-001 | M5: Hardened recently
A6: Platform & Auth | B6: PF-003 | C6: Auth Context + Permission Gating | D6: AuthContext exposes user + per-app permissions. Components gate features via useAuth(). Permissions auto-refresh on user change. | E6: Built | F6: P0 | G6: Approved | H6: Frontend Platform | I6: M | J6: v1.0 | K6: Q1 2026 | L6: PF-001
A7: Platform & Auth | B7: PF-004 | C7: First-Time Market Selector Modal | D7: Non-dismissable modal blocks app on first login until market is picked. Subsequent logins skip it. Persisted to localStorage. | E7: Built | F7: P1 | G7: Approved | H7: Frontend Platform | I7: S | J7: v1.1 | K7: Q2 2026 | L7: PF-005
A8: Platform & Auth | B8: PF-005 | C8: Multi-Market Configuration | D8: Markets config in frontend/src/config/markets.ts. NorCal live; SoCal/PNW/TX/NE shown as 'Coming soon'. Maps labels to remote MARKET values. | E8: Built | F8: P1 | G8: Approved | H8: Frontend Platform | I8: S | J8: v1.1 | K8: Q2 2026 | L8: — | M8: More markets pending data
A9: Platform & Auth | B9: PF-006 | C9: Theme Provider (Light/Dark) | D9: ThemeProvider exposes theme + setTheme. All bespoke components consume it. Defaults to dark; html.dark forced on bootstrap. | E9: Built | F9: P2 | G9: Approved | H9: Frontend Platform | I9: S | J9: v1.0 | K9: Q1 2026 | L9: —
A10: Platform & Auth | B10: PF-007 | C10: User Profile Dropdown | D10: Sidebar avatar opens consolidated menu — Market / Settings / Feedback / Logout. Inline when expanded; portal popover when collapsed. | E10: Built | F10: P1 | G10: Approved | H10: Frontend Platform | I10: S | J10: v1.1 | K10: Q2 2026 | L10: PF-005, ST-001
A11: Platform & Auth | B11: PF-008 | C11: Collapsible Left Sidebar | D11: Claude-style sidebar with collapse/expand, navigation rail, per-stream session history, profile menu at bottom. | E11: Built | F11: P1 | G11: Approved | H11: Frontend Platform | I11: M | J11: v1.1 | K11: Q2 2026 | L11: —
A12: Platform & Auth | B12: PF-009 | C12: Platform Bus (Inter-App Navigation) | D12: Pub/sub bus for navigation intents (NAVIGATE_TO_APP). Shell subscribes and routes. Used by chat to deep-link into apps. | E12: Built | F12: P1 | G12: Approved | H12: Frontend Platform | I12: M | J12: v1.0 | K12: Q1 2026 | L12: —
A13: Platform & Auth | B13: PF-010 | C13: App Registry | D13: Dynamic registry of mountable apps with display name, icon, route, default chat stream, permission key. Drives sidebar nav and AppSlot. | E13: Built | F13: P1 | G13: Approved | H13: Frontend Platform | I13: M | J13: v1.0 | K13: Q1 2026 | L13: PF-009
A14: Platform & Auth | B14: PF-011 | C14: Login UI with Fluid Background | D14: Split-pane layout, animated fluid gradient background, theme-aware Naavik branding. Username + password + show/hide toggle. | E14: Built | F14: P2 | G14: Approved | H14: Design | I14: S | J14: v1.0 | K14: Q1 2026 | L14: PF-001
A15: Chat & Intent | B15: CI-001 | C15: Multi-Stream Chat Orchestrator | D15: Five chat streams (universal, observability, appgen, provision, knowledge) with stream-specific prompts and starter suggestions. | E15: Built | F15: P0 | G15: Approved | H15: Agent Team | I15: M | J15: v1.0 | K15: Q1 2026 | L15: —
A16: Chat & Intent | B16: CI-002 | C16: Agent V3 Orchestrator | D16: True OpenAI function-calling loop. Tools execute in parallel via Promise.allSettled. MAX_ITERATIONS=8, model gpt-4o-mini. | E16: Built | F16: P0 | G16: Approved | H16: Agent Team | I16: L | J16: v1.1 | K16: Q2 2026 | L16: —
A17: Chat & Intent | B17: CI-003 | C17: 21-Tool Agent Registry | D17: Tools include find_site, get_worst_offenders, RCA, KPI dashboard, query_data, generate_report, knowledge, navigation. | E17: Built | F17: P0 | G17: Approved | H17: Agent Team | I17: L | J17: v1.0 | K17: Q1 2026 | L17: CI-002
A18: Chat & Intent | B18: CI-004 | C18: Site-Analysis Tool Suite (10 tools) | D18: topology, config_changes, neighbor_relations, ret_changes, site_outages, neighbor_outages, hourly_trends, kpi_impact_breakdown, ticket_history, compare_with_cluster. | E18: Built | F18: P0 | G18: Approved | H18: Agent Team | I18: XL | J18: v1.1 | K18: Q2 2026 | L18: DL-002
A19: Chat & Intent | B19: CI-005 | C19: Intent Classifier | D19: Semantic + explicit + context-aware classifier. Routes 'show map', 'explain RCA', 'build app' to the right stream and tool path. | E19: Built | F19: P1 | G19: Approved | H19: Agent Team | I19: M | J19: v1.0 | K19: Q1 2026 | L19: —
A20: Chat & Intent | B20: CI-006 | C20: Navigation Orchestrator | D20: Three-layer intent detection turning chat into platform-bus events. 'Open observe' navigates; 'sites with alarms' also sets map layer. | E20: Built | F20: P1 | G20: Approved | H20: Agent Team | I20: M | J20: v1.0 | K20: Q1 2026 | L20: PF-009, CI-005
... A27: Chat & Intent | B27: CI-013 | C27: Multi-Attachment Support | D27: Up to 3 attachments per message — CSVs ≤750KB, images ≤900KB, text ≤120KB. Sent inline with chat payload. | E27: Built | F27: P2 | G27: Approved | H27: Frontend Platform | I27: M | J27: v1.0 | K27: Q1 2026 | L27: —
A28: Chat & Intent | B28: CI-014 | C28: Per-Stream Session History | D28: Sidebar shows recent prompts grouped by stream. Click to re-send. History local to React state (not yet persisted). | E28: Built | F28: P2 | G28: Approved | H28: Frontend Platform | I28: S | J28: v1.0 | K28: Q1 2026 | L28: — | M28: Persistence planned for v1.3
A29: Chat & Intent | B29: CI-015 | C29: V2 Chat Fallback | D29: Legacy V2 orchestrator (no tool calling) as fallback. Toggle via localStorage or Settings. | E29: Built | F29: P3 | G29: Approved | H29: Agent Team | I29: S | J29: v0.9 | K29: Q4 2025 | L29: — | M29: Will be deprecated in v2.0
A30: Naavik Observe | B30: OB-001 | C30: Mapbox Site Map | D30: Interactive Mapbox-GL map showing 6,800+ sites for selected market. Zoom/pan/click. Color-coded by severity. | E30: Built | F30: P0 | G30: Approved | H30: Observe Team | I30: L | J30: v1.0 | K30: Q1 2026 | L30: DL-014
A31: Naavik Observe | B31: OB-002 | C31: Site Layer Toggles | D31: Three layers — degraded, outage, overutilized. Driven by set_map_layer from chat or direct UI clicks. | E31: Built | F31: P0 | G31: Approved | H31: Observe Team | I31: M | J31: v1.0 | K31: Q1 2026 | L31: OB-001
A32: Naavik Observe | B32: OB-003 | C32: Site Detail Panel — 5 Tabs | D32: Click site → tabbed panel. Site KPI, RCA, Operational, Topology, AI Analyzer. Summary vs Diagnostic mode toggle. | E32: Built | F32: P0 | G32: Approved | H32: Observe Team | I32: L | J32: v1.1 | K32: Q2 2026 | L32: OB-001
A33: Naavik Observe | B33: OB-004 | C33: Summary Mode (Animated RCA) | D33: RCA-focused summary with step-by-step strongest-factors animation, mini-map for related neighbors. | E33: Built | F33: P1 | G33: Approved | H33: Observe Team | I33: M | J33: v1.0 | K33: Q1 2026 | L33: OB-003
A34: Naavik Observe | B34: OB-005 | C34: Diagnostic Mode | D34: Full telemetry — KPI charts, hourly insights, anomaly callouts. Sub-second loads via local mirror. | E34: Built | F34: P0 | G34: Approved | H34: Observe Team | I34: L | J34: v1.2 | K34: Q2 2026 | L34: DL-002, DL-012
A35: Naavik Observe | B35: OB-006 | C35: Cell Topology View | D35: Cells listed with band, technology, azimuth, height, anomaly. Replaced by TopologyGrid (band tiles). | E35: Built | F35: P1 | G35: Approved | H35: Observe Team | I35: M | J35: v1.2 | K35: Q2 2026 | L35: UI-020
A36: Naavik Observe | B36: OB-007 | C36: KPI Dashboard (Daily/Hourly) | D36: Multi-KPI line-chart with daily 7-90d / hourly 24-72h. KPI selector with 16 grouped standard KPIs + custom search. | E36: Built | F36: P0 | G36: Approved | H36: Observe Team | I36: L | J36: v1.0 | K36: Q1 2026 | L36: DL-015
A37: Naavik Observe | B37: OB-008 | C37: Multi-KPI Comparison | D37: Up to 8 KPIs simultaneously, unit-aware Y-axis, anomaly markers, shared 20-color palette. | E37: Built | F37: P1 | G37: Approved | H37: Observe Team | I37: M | J37: v1.0 | K37: Q1 2026 | L37: OB-007
A38: Naavik Observe | B38: OB-009 | C38: Hourly Insights Panel | D38: Time-of-day pattern analysis — peak hours, busy-hour deviation, anomaly hours, weekly comparison. | E38: Built | F38: P1 | G38: Approved | H38: Observe Team | I38: M | J38: v1.1 | K38: Q2 2026 | L38: OB-007
A39: Naavik Observe | B39: OB-010 | C39: Mobility Trends | D39: HOSR, inter/intra-frequency HO, throughput-per-handover. Used by analyzer for coverage detection. | E39: Built | F39: P2 | G39: Approved | H39: Observe Team | I39: M | J39: v1.1 | K39: Q2 2026 | L39: —
A40: Naavik Observe | B40: OB-011 | C40: Outage Timeline | D40: Per-cell outage events on 24h or 7d strip. Shows metric type and snapshot hour. | E40: Built | F40: P2 | G40: Approved | H40: Observe Team | I40: M | J40: v1.1 | K40: Q2 2026 | L40: —
A41: Naavik Observe | B41: OB-012 | C41: Traffic Profile Dashboard | D41: DL/UL volume + PRB-utilisation profile. Distinguishes capacity from coverage issues. | E41: Built | F41: P2 | G41: Approved | H41: Observe Team | I41: M | J41: v1.1 | K41: Q2 2026 | L41: —
A42: Naavik Observe | B42: OB-013 | C42: Cross-Correlator (KPI Relationships) | D42: Pairwise correlation between KPIs. Surfaces which pairs move together or diverge. | E42: Planned | F42: P2 | G42: Pending | H42: Observe Team | I42: L | J42: v1.4 | K42: Q3 2026 | L42: OB-007 | M42: Removed for redesign
A43: Naavik Observe | B43: OB-014 | C43: AI Analyzer Tab | D43: Dedicated tab in site detail. Runs deep investigation (8-10 tools parallel). Hero severity card + 4 verdict sections + trail + evidence. | E43: Built | F43: P0 | G43: Approved | H43: Agent Team | I43: L | J43: v1.2 | K43: Q2 2026 | L43: CI-002, CI-004
A44: Naavik Observe | B44: OB-015 | C44: Worst Offenders Ranking | D44: Daily ranked list by total CQX impact. Each row links to site detail. Inline 'Explain RCA' button. | E44: Built | F44: P0 | G44: Approved | H44: Observe Team | I44: M | J44: v1.0 | K44: Q1 2026 | L44: DL-002
A45: Naavik Observe | B45: OB-016 | C45: Cluster Comparison | D45: Site KPI vs cluster peers. Returns rank, percentile, outlier flag (>2σ). Bar chart with source highlighted. | E45: Built | F45: P1 | G45: Approved | H45: Agent Team | I45: M | J45: v1.2 | K45: Q2 2026 | L45: CI-004
A46: Naavik Observe | B46: OB-017 | C46: Neighbor Map Overlay | D46: Top neighbors as dashed lines on map with HO-share labels. Click pivots panel to that site. | E46: Built | F46: P1 | G46: Approved | H46: Observe Team | I46: M | J46: v1.1 | K46: Q2 2026 | L46: OB-001, OB-003
A47: Naavik Observe | B47: OB-018 | C47: Operational Info Workbench | D47: Aggregates alarms, tickets, config, outages, EIM for site + neighbors over 7d. Sub-tabs per type. | E47: Built | F47: P1 | G47: Approved | H47: Observe Team | I47: L | J47: v1.1 | K47: Q2 2026 | L47: DL-002
...
